<?xml version="1.0"?>
<robot name="industrial_robot">

  <!-- Define materials -->
  <material name="aluminum">
    <color rgba="0.7 0.7 0.7 1"/>
  </material>
  
  <material name="dark_gray">
    <color rgba="0.3 0.3 0.3 1"/>
  </material>

  <material name="black">
    <color rgba="0.1 0.1 0.1 1"/>
  </material>

  <!-- Base Link -->
  <link name="base_link"/>

  <!-- Main Chassis (Rectangular Frame) -->
  <link name="chassis">
    <visual>
      <origin xyz="0 0 0" rpy="0 0 0"/>
      <geometry>
        <box size="0.457 0.305 0.152"/>  <!-- 18" x 12" x 6" converted to meters -->
      </geometry>
      <material name="aluminum"/>
    </visual>
    <collision>
      <origin xyz="0 0 0" rpy="0 0 0"/>
      <geometry>
        <box size="0.457 0.305 0.152"/>
      </geometry>
    </collision>
    <inertial>
      <origin xyz="0 0 0" rpy="0 0 0"/>
      <mass value="15.0"/>  <!-- Heavier for aluminum frame -->
      <inertia ixx="0.5" ixy="0" ixz="0" iyy="0.5" iyz="0" izz="0.8"/>
    </inertial>
  </link>

  <!-- Vertical Mast -->
  <link name="mast">
    <visual>
      <origin xyz="0 0 0" rpy="0 0 0"/>
      <geometry>
        <cylinder radius="0.025" length="0.8"/>  <!-- 2" diameter, 32" tall mast -->
      </geometry>
      <material name="dark_gray"/>
    </visual>
    <collision>
      <origin xyz="0 0 0" rpy="0 0 0"/>
      <geometry>
        <cylinder radius="0.025" length="0.8"/>
      </geometry>
    </collision>
    <inertial>
      <origin xyz="0 0 0" rpy="0 0 0"/>
      <mass value="3.0"/>
      <inertia ixx="0.16" ixy="0" ixz="0" iyy="0.16" iyz="0" izz="0.001"/>
    </inertial>
  </link>

  <!-- Front Wheel (10 inch = 0.254m diameter, 0.127m radius) -->
  <link name="front_wheel">
    <visual>
      <origin xyz="0 0 0" rpy="1.5708 0 0"/>
      <geometry>
        <cylinder radius="0.127" length="0.06"/>
      </geometry>
      <material name="black"/>
    </visual>
    <collision>
      <origin xyz="0 0 0" rpy="1.5708 0 0"/>
      <geometry>
        <cylinder radius="0.127" length="0.06"/>
      </geometry>
    </collision>
    <inertial>
      <origin xyz="0 0 0" rpy="1.5708 0 0"/>
      <mass value="2.5"/>
      <inertia ixx="0.02" ixy="0" ixz="0" iyy="0.02" iyz="0" izz="0.02"/>
    </inertial>
  </link>

  <!-- Left Rear Wheel -->
  <link name="left_rear_wheel">
    <visual>
      <origin xyz="0 0 0" rpy="1.5708 0 0"/>
      <geometry>
        <cylinder radius="0.127" length="0.06"/>
      </geometry>
      <material name="black"/>
    </visual>
    <collision>
      <origin xyz="0 0 0" rpy="1.5708 0 0"/>
      <geometry>
        <cylinder radius="0.127" length="0.06"/>
      </geometry>
    </collision>
    <inertial>
      <origin xyz="0 0 0" rpy="1.5708 0 0"/>
      <mass value="2.5"/>
      <inertia ixx="0.02" ixy="0" ixz="0" iyy="0.02" iyz="0" izz="0.02"/>
    </inertial>
  </link>

  <!-- Right Rear Wheel -->
  <link name="right_rear_wheel">
    <visual>
      <origin xyz="0 0 0" rpy="1.5708 0 0"/>
      <geometry>
        <cylinder radius="0.127" length="0.06"/>
      </geometry>
      <material name="black"/>
    </visual>
    <collision>
      <origin xyz="0 0 0" rpy="1.5708 0 0"/>
      <geometry>
        <cylinder radius="0.127" length="0.06"/>
      </geometry>
    </collision>
    <inertial>
      <origin xyz="0 0 0" rpy="1.5708 0 0"/>
      <mass value="2.5"/>
      <inertia ixx="0.02" ixy="0" ixz="0" iyy="0.02" iyz="0" izz="0.02"/>
    </inertial>
  </link>

  <!-- Base to Chassis Joint -->
  <joint name="base_to_chassis" type="fixed">
    <parent link="base_link"/>
    <child link="chassis"/>
    <origin xyz="0 0 0.203" rpy="0 0 0"/>  <!-- Chassis center at wheel radius + half chassis height -->
  </joint>

  <!-- Chassis to Mast Joint -->
  <joint name="chassis_to_mast" type="fixed">
    <parent link="chassis"/>
    <child link="mast"/>
    <origin xyz="0 0 0.476" rpy="0 0 0"/>  <!-- Mast base at top of chassis + half mast height -->
  </joint>

  <!-- Front Wheel Joint (front center) -->
  <joint name="front_wheel_joint" type="continuous">
    <parent link="chassis"/>
    <child link="front_wheel"/>
    <origin xyz="0.15 0 -0.076" rpy="0 0 0"/>  <!-- Front of chassis, wheel touching ground -->
    <axis xyz="0 1 0"/>
  </joint>

  <!-- Left Rear Wheel Joint (triangular position) -->
  <joint name="left_rear_wheel_joint" type="continuous">
    <parent link="chassis"/>
    <child link="left_rear_wheel"/>
    <origin xyz="-0.15 0.13 -0.076" rpy="0 0 0"/>  <!-- Left rear, triangular formation -->
    <axis xyz="0 1 0"/>
  </joint>

  <!-- Right Rear Wheel Joint (triangular position) -->
  <joint name="right_rear_wheel_joint" type="continuous">
    <parent link="chassis"/>
    <child link="right_rear_wheel"/>
    <origin xyz="-0.15 -0.13 -0.076" rpy="0 0 0"/>  <!-- Right rear, triangular formation -->
    <axis xyz="0 1 0"/>
  </joint>

  <!-- Gazebo Plugins - Omnidirectional drive for 3-wheel config -->
  <gazebo>
    <plugin filename="gz-sim-diff-drive-system" name="gz::sim::systems::DiffDrive">
      <left_joint>left_rear_wheel_joint</left_joint>
      <right_joint>right_rear_wheel_joint</right_joint>
      <wheel_separation>0.26</wheel_separation>  <!-- Distance between rear wheels -->
      <wheel_radius>0.127</wheel_radius>
      <odom_publish_frequency>30</odom_publish_frequency>
      <max_linear_acceleration>1</max_linear_acceleration>
      <min_linear_acceleration>-1</min_linear_acceleration>
      <max_angular_acceleration>2</max_angular_acceleration>
      <min_angular_acceleration>-2</min_angular_acceleration>
      <max_linear_velocity>2.0</max_linear_velocity>  <!-- Higher speed for larger robot -->
      <min_linear_velocity>-2.0</min_linear_velocity>
      <max_angular_velocity>2</max_angular_velocity>
      <min_angular_velocity>-2</min_angular_velocity>
      <topic>/cmd_vel</topic>
      <odom_topic>/odom</odom_topic>
      <frame_id>odom</frame_id>
      <child_frame_id>base_link</child_frame_id>
    </plugin>
  </gazebo>

  <!-- Gazebo Colors -->
  <gazebo reference="chassis">
    <material>
      <ambient>0.7 0.7 0.7 1</ambient>
      <diffuse>0.7 0.7 0.7 1</diffuse>
      <specular>0.9 0.9 0.9 1</specular>
    </material>
  </gazebo>

  <gazebo reference="mast">
    <material>
      <ambient>0.3 0.3 0.3 1</ambient>
      <diffuse>0.3 0.3 0.3 1</diffuse>
      <specular>0.5 0.5 0.5 1</specular>
    </material>
  </gazebo>

  <gazebo reference="front_wheel">
    <material>
      <ambient>0.1 0.1 0.1 1</ambient>
      <diffuse>0.1 0.1 0.1 1</diffuse>
      <specular>0.1 0.1 0.1 1</specular>
    </material>
  </gazebo>

  <gazebo reference="left_rear_wheel">
    <material>
      <ambient>0.1 0.1 0.1 1</ambient>
      <diffuse>0.1 0.1 0.1 1</diffuse>
      <specular>0.1 0.1 0.1 1</specular>
    </material>
  </gazebo>

  <gazebo reference="right_rear_wheel">
    <material>
      <ambient>0.1 0.1 0.1 1</ambient>
      <diffuse>0.1 0.1 0.1 1</diffuse>
      <specular>0.1 0.1 0.1 1</specular>
    </material>
  </gazebo>

</robot>